<?xml version="1.0" ?>
<!-- =================================================================================== -->
<!-- |    This document was autogenerated by xacro from ostrich_urdf.xacro             | -->
<!-- |    EDITING THIS FILE BY HAND IS NOT RECOMMENDED                                 | -->
<!-- =================================================================================== -->
<robot name="ostrich_urdf">
  <material name="silver">
    <color rgba="0.700 0.700 0.700 1.000"/>
  </material>
  <transmission name="rot1_tran">
    <type>transmission_interface/SimpleTransmission</type>
    <joint name="rot1">
      <hardwareInterface>hardware_interface/EffortJointInterface</hardwareInterface>
    </joint>
    <actuator name="rot1_actr">
      <hardwareInterface>hardware_interface/EffortJointInterface</hardwareInterface>
      <mechanicalReduction>1</mechanicalReduction>
    </actuator>
  </transmission>
  <transmission name="rot2_tran">
    <type>transmission_interface/SimpleTransmission</type>
    <joint name="rot2">
      <hardwareInterface>hardware_interface/EffortJointInterface</hardwareInterface>
    </joint>
    <actuator name="rot2_actr">
      <hardwareInterface>hardware_interface/EffortJointInterface</hardwareInterface>
      <mechanicalReduction>1</mechanicalReduction>
    </actuator>
  </transmission>
  <transmission name="rot3_tran">
    <type>transmission_interface/SimpleTransmission</type>
    <joint name="rot3">
      <hardwareInterface>hardware_interface/EffortJointInterface</hardwareInterface>
    </joint>
    <actuator name="rot3_actr">
      <hardwareInterface>hardware_interface/EffortJointInterface</hardwareInterface>
      <mechanicalReduction>1</mechanicalReduction>
    </actuator>
  </transmission>
  <transmission name="rot4_tran">
    <type>transmission_interface/SimpleTransmission</type>
    <joint name="rot4">
      <hardwareInterface>hardware_interface/EffortJointInterface</hardwareInterface>
    </joint>
    <actuator name="rot4_actr">
      <hardwareInterface>hardware_interface/EffortJointInterface</hardwareInterface>
      <mechanicalReduction>1</mechanicalReduction>
    </actuator>
  </transmission>
  <transmission name="rot5_tran">
    <type>transmission_interface/SimpleTransmission</type>
    <joint name="rot5">
      <hardwareInterface>hardware_interface/EffortJointInterface</hardwareInterface>
    </joint>
    <actuator name="rot5_actr">
      <hardwareInterface>hardware_interface/EffortJointInterface</hardwareInterface>
      <mechanicalReduction>1</mechanicalReduction>
    </actuator>
  </transmission>
  <transmission name="rot6_tran">
    <type>transmission_interface/SimpleTransmission</type>
    <joint name="rot6">
      <hardwareInterface>hardware_interface/EffortJointInterface</hardwareInterface>
    </joint>
    <actuator name="rot6_actr">
      <hardwareInterface>hardware_interface/EffortJointInterface</hardwareInterface>
      <mechanicalReduction>1</mechanicalReduction>
    </actuator>
  </transmission>
  <gazebo>
    <plugin filename="libgazebo_ros_control.so" name="control"/>
  </gazebo>
  <gazebo reference="base_link">
    <material>Gazebo/Silver</material>
    <mu1>0.2</mu1>
    <mu2>0.2</mu2>
    <selfCollide>true</selfCollide>
    <gravity>true</gravity>
  </gazebo>
  <gazebo reference="arm1_1">
    <material>Gazebo/Silver</material>
    <mu1>0.2</mu1>
    <mu2>0.2</mu2>
    <selfCollide>true</selfCollide>
  </gazebo>
  <gazebo reference="arm2_1">
    <material>Gazebo/Silver</material>
    <mu1>0.2</mu1>
    <mu2>0.2</mu2>
    <selfCollide>true</selfCollide>
  </gazebo>
  <gazebo reference="arm3_1">
    <material>Gazebo/Silver</material>
    <mu1>0.2</mu1>
    <mu2>0.2</mu2>
    <selfCollide>true</selfCollide>
  </gazebo>
  <gazebo reference="arm4_1">
    <material>Gazebo/Silver</material>
    <mu1>0.2</mu1>
    <mu2>0.2</mu2>
    <selfCollide>true</selfCollide>
  </gazebo>
  <gazebo reference="arm5_1">
    <material>Gazebo/Silver</material>
    <mu1>0.2</mu1>
    <mu2>0.2</mu2>
    <selfCollide>true</selfCollide>
  </gazebo>
  <gazebo reference="arm6_1">
    <material>Gazebo/Silver</material>
    <mu1>0.2</mu1>
    <mu2>0.2</mu2>
    <selfCollide>true</selfCollide>
  </gazebo>
  <link name="base_link">
    <inertial>
      <origin rpy="0 0 0" xyz="2.7578935128829445e-17 5.515787025765889e-17 0.002761975022526879"/>
      <mass value="2.5887632628187394"/>
      <inertia ixx="0.012992" ixy="0.0" ixz="-0.0" iyy="0.012992" iyz="0.0" izz="0.025967"/>
    </inertial>
    <visual>
      <origin rpy="0 0 0" xyz="0 0 0"/>
      <geometry>
        <mesh filename="package://ostrich_urdf_description/meshes/base_link.stl" scale="0.001 0.001 0.001"/>
      </geometry>
      <material name="silver"/>
    </visual>
    <collision>
      <origin rpy="0 0 0" xyz="0 0 0"/>
      <geometry>
        <mesh filename="package://ostrich_urdf_description/meshes/base_link.stl" scale="0.001 0.001 0.001"/>
      </geometry>
    </collision>
  </link>
  <link name="arm1_1">
    <inertial>
      <origin rpy="0 0 0" xyz="0.0 -7.328670674595108e-10 0.12579457405148342"/>
      <mass value="17.06120317992324"/>
      <inertia ixx="0.086124" ixy="0.0" ixz="0.0" iyy="0.089734" iyz="-0.0" izz="0.02783"/>
    </inertial>
    <visual>
      <origin rpy="0 0 0" xyz="-0.0 -0.0 -0.005"/>
      <geometry>
        <mesh filename="package://ostrich_urdf_description/meshes/arm1_1.stl" scale="0.001 0.001 0.001"/>
      </geometry>
      <material name="silver"/>
    </visual>
    <collision>
      <origin rpy="0 0 0" xyz="-0.0 -0.0 -0.005"/>
      <geometry>
        <mesh filename="package://ostrich_urdf_description/meshes/arm1_1.stl" scale="0.001 0.001 0.001"/>
      </geometry>
    </collision>
  </link>
  <link name="arm2_1">
    <inertial>
      <origin rpy="0 0 0" xyz="-0.05999999999732328 3.032800993368656e-08 0.17138913427023483"/>
      <mass value="27.17363423214535"/>
      <inertia ixx="0.332477" ixy="0.0" ixz="0.0" iyy="0.355819" iyz="-0.0" izz="0.064159"/>
    </inertial>
    <visual>
      <origin rpy="0 0 0" xyz="-0.06 -0.0 -0.185"/>
      <geometry>
        <mesh filename="package://ostrich_urdf_description/meshes/arm2_1.stl" scale="0.001 0.001 0.001"/>
      </geometry>
      <material name="silver"/>
    </visual>
    <collision>
      <origin rpy="0 0 0" xyz="-0.06 -0.0 -0.185"/>
      <geometry>
        <mesh filename="package://ostrich_urdf_description/meshes/arm2_1.stl" scale="0.001 0.001 0.001"/>
      </geometry>
    </collision>
  </link>
  <link name="arm3_1">
    <inertial>
      <origin rpy="0 0 0" xyz="-0.0599999999957338 4.493635609449077e-10 0.1518601041469002"/>
      <mass value="23.646526866373804"/>
      <inertia ixx="0.256501" ixy="0.0" ixz="-0.0" iyy="0.276234" iyz="0.0" izz="0.053214"/>
    </inertial>
    <visual>
      <origin rpy="0 0 0" xyz="-0.06 -0.0 -0.48"/>
      <geometry>
        <mesh filename="package://ostrich_urdf_description/meshes/arm3_1.stl" scale="0.001 0.001 0.001"/>
      </geometry>
      <material name="silver"/>
    </visual>
    <collision>
      <origin rpy="0 0 0" xyz="-0.06 -0.0 -0.48"/>
      <geometry>
        <mesh filename="package://ostrich_urdf_description/meshes/arm3_1.stl" scale="0.001 0.001 0.001"/>
      </geometry>
    </collision>
  </link>
  <link name="arm4_1">
    <inertial>
      <origin rpy="0 0 0" xyz="0.0 -1.0276776143111988e-09 0.18482539606118964"/>
      <mass value="24.429919386960766"/>
      <inertia ixx="0.27668" ixy="-0.0" ixz="0.0" iyy="0.28029" iyz="0.0" izz="0.037009"/>
    </inertial>
    <visual>
      <origin rpy="0 0 0" xyz="-0.0 -0.0 -0.815"/>
      <geometry>
        <mesh filename="package://ostrich_urdf_description/meshes/arm4_1.stl" scale="0.001 0.001 0.001"/>
      </geometry>
      <material name="silver"/>
    </visual>
    <collision>
      <origin rpy="0 0 0" xyz="-0.0 -0.0 -0.815"/>
      <geometry>
        <mesh filename="package://ostrich_urdf_description/meshes/arm4_1.stl" scale="0.001 0.001 0.001"/>
      </geometry>
    </collision>
  </link>
  <link name="arm5_1">
    <inertial>
      <origin rpy="0 0 0" xyz="-0.0599999999957338 4.493635609449077e-10 0.15186010414690032"/>
      <mass value="23.646526866373804"/>
      <inertia ixx="0.256501" ixy="0.0" ixz="-0.0" iyy="0.276234" iyz="0.0" izz="0.053214"/>
    </inertial>
    <visual>
      <origin rpy="0 0 0" xyz="-0.06 -0.0 -1.11"/>
      <geometry>
        <mesh filename="package://ostrich_urdf_description/meshes/arm5_1.stl" scale="0.001 0.001 0.001"/>
      </geometry>
      <material name="silver"/>
    </visual>
    <collision>
      <origin rpy="0 0 0" xyz="-0.06 -0.0 -1.11"/>
      <geometry>
        <mesh filename="package://ostrich_urdf_description/meshes/arm5_1.stl" scale="0.001 0.001 0.001"/>
      </geometry>
    </collision>
  </link>
  <link name="arm6_1">
    <inertial>
      <origin rpy="0 0 0" xyz="-1.0318772372603758e-17 0.0 0.02935671431989184"/>
      <mass value="3.459487791334984"/>
      <inertia ixx="0.003185" ixy="0.0" ixz="-0.0" iyy="0.003185" iyz="-0.0" izz="0.003954"/>
    </inertial>
    <visual>
      <origin rpy="0 0 0" xyz="-0.0 -0.0 -1.445"/>
      <geometry>
        <mesh filename="package://ostrich_urdf_description/meshes/arm6_1.stl" scale="0.001 0.001 0.001"/>
      </geometry>
      <material name="silver"/>
    </visual>
    <collision>
      <origin rpy="0 0 0" xyz="-0.0 -0.0 -1.445"/>
      <geometry>
        <mesh filename="package://ostrich_urdf_description/meshes/arm6_1.stl" scale="0.001 0.001 0.001"/>
      </geometry>
    </collision>
  </link>
  <joint name="rot1" type="continuous">
    <origin rpy="0 0 0" xyz="0.0 0.0 0.005"/>
    <parent link="base_link"/>
    <child link="arm1_1"/>
    <axis xyz="0.0 0.0 1.0"/>
  </joint>
  <joint name="rot2" type="continuous">
    <origin rpy="0 0 0" xyz="0.06 0.0 0.18"/>
    <parent link="arm1_1"/>
    <child link="arm2_1"/>
    <axis xyz="1.0 0.0 0.0"/>
  </joint>
  <joint name="rot3" type="continuous">
    <origin rpy="0 0 0" xyz="0.0 0.0 0.295"/>
    <parent link="arm2_1"/>
    <child link="arm3_1"/>
    <axis xyz="-1.0 0.0 0.0"/>
  </joint>
  <joint name="rot4" type="continuous">
    <origin rpy="0 0 0" xyz="-0.06 0.0 0.335"/>
    <parent link="arm3_1"/>
    <child link="arm4_1"/>
    <axis xyz="0.0 0.0 -1.0"/>
  </joint>
  <joint name="rot5" type="continuous">
    <origin rpy="0 0 0" xyz="0.06 0.0 0.295"/>
    <parent link="arm4_1"/>
    <child link="arm5_1"/>
    <axis xyz="1.0 0.0 0.0"/>
  </joint>
  <joint name="rot6" type="continuous">
    <origin rpy="0 0 0" xyz="-0.06 0.0 0.335"/>
    <parent link="arm5_1"/>
    <child link="arm6_1"/>
    <axis xyz="0.0 0.0 -1.0"/>
  </joint>
</robot>

